Workbook

Sheet Настройки
B1: КАЛЬКУЛЯТОР СТОИМОСТИ УСЛУГ СТРОИТЕЛЬНОГО ЭКСПЕРТА
B2: ИП, УСН «доходы» 6% • Ярославская область • работа для себя, без привлечения сторонних специалистов • ставки задаются здесь
B3: Параметр | C3: Значение | D3: Пояснение
B4: ⚙ 1. БАЗОВЫЕ СТАВКИ
B5: Ставка часа работы эксперта, ₽/час | C5: 1000 | D5: Ваша базовая ставка. От неё считаются все виды работ на трёх листах-калькуляторах.
B6: Стоимость 1 км пробега (топливо + амортизация авто), ₽/км | C6: 12 | D6: ЯО, осень 2026: АИ-95 ≈ 67–70 ₽/л × 9 л/100 км ≈ 6 ₽/км + амортизация/шины ≈ 6 ₽/км. ОСАГО и ТО — на листе «Накладные». Время в пути считается отдельно (ниже, п.6).
B7: 📈 2. НАКЛАДНЫЕ РАСХОДЫ И НАЦЕНКА
B8: % накладных расходов (авто с листа «Накладные расходы») | C8: ='Накладные расходы'!C26 -> 0.078684006 | D8: Меняйте исходные данные на листе «Накладные расходы» — здесь пересчитается автоматически.
B9: % плановой наценки / прибыли | C9: 0.3 | D9: Было 100%. Снижено до 30%, чтобы цены попали в рынок Ярославля (см. лист «Рынок ЯО»): рынок платит ≈1 400 ₽ за час вашей работы.
B10: % надбавки за срочность (осмотр/акт в течение суток) | C10: 0.2 | D10: Применяется, если на листе-калькуляторе включена срочность.
B11: 💸 3. НАЛОГООБЛОЖЕНИЕ
B12: Ставка налога УСН «доходы» | C12: 0.06 | D12: В Ярославской области пониженной ставки для «доходов» нет (Закон ЯО № 69-з даёт льготы только для «доходы минус расходы»). Взносы ИП 2026: 57 390 ₽ + 1% сверх 300 тыс. — уменьшают налог полностью, поэтому 6% ≈ вся нагрузка.
B13: 🧰 4. ДОПОЛНИТЕЛЬНОЕ ОБОРУДОВАНИЕ (тариф за использование при выезде, ₽)
B14: Влагомер | C14: 300
B15: Тепловизор | C15: 800
B16: Лазерный дальномер | C16: 150
B17: Эндоскоп (осмотр скрытых полостей) | C17: 500 | D17: Эти суммы — ваша условная надбавка за использование инструмента (износ, время на замер). Правьте под себя.
B18: 🖨 5. ОФОРМЛЕНИЕ ДОКУМЕНТОВ
B19: Стоимость печати/брошюровки 1 экземпляра акта, ₽ | C19: 200
B20: Количество экземпляров по умолчанию | C20: 2
B22: Легенда: 🔵 синий текст на жёлтом = вводите вручную ⚫ чёрный на зелёном = формула 🟢 зелёный на голубом = ссылка с другого листа
B24: 📍 6. ЯРОСЛАВСКАЯ ОБЛАСТЬ — ВЫЕЗДЫ И ЦЕНА
B25: Средняя скорость в пути по области, км/ч | C25: 50 | D25: Город + районные дороги. Время в пути оплачивается по часовой ставке и входит в стоимость транспорта на листах.
B26: Доля ставки за время в пути | C26: 1 | D26: 100% = час дороги стоит как час работы. Поставьте 50%, если хотите брать за дорогу дешевле.
B27: Округление итоговой цены вверх до, ₽ | C27: 500 | D27: Клиенту — круглая сумма.

Sheet Накладные расходы
B1: НАКЛАДНЫЕ РАСХОДЫ ИП (в месяц)
B2: Результат автоматически используется на листе «Настройки» (% накладных, ячейка C8)
B3: Параметр | C3: Значение | D3: Пояснение
B4: 📞 1. ПОСТОЯННЫЕ ЕЖЕМЕСЯЧНЫЕ РАСХОДЫ
B5: Связь, интернет | C5: 3000
B6: Реклама, сайт, визитки | C6: 2000
B7: Бухгалтерия / налоговый учёт | C7: 3000
B8: Банковское обслуживание / эквайринг | C8: 0
B9: Аренда офиса / коворкинга (если есть) | C9: 3000
B10: Итого постоянные расходы | C10: =SUM(C5:C9) -> 11000
B11: 🔧 2. АМОРТИЗАЦИЯ ИНСТРУМЕНТА
B12: Стоимость инструмента (влагомер, дальномер, тепловизор и т.д.), ₽ | C12: 50000
B13: Срок службы, лет | C13: 5
B14: Амортизация инструмента в месяц (расчёт) | C14: =C12/(C13*12) -> 833.33333
B15: 🚗 3. АВТОМОБИЛЬ (без топлива — оно считается по км в заказах)
B16: ОСАГО, ТО, ремонт — в год, ₽ | C16: 50000
B17: Амортизация автомобиля — в год, ₽ | C17: 0 | D17: Оставьте 0: амортизация авто уже заложена в ₽/км на листе «Настройки».
B18: Итого авто в месяц (расчёт) | C18: =(C16+C17)/12 -> 4166.6667
B19: 📜 4. СТРАХОВАНИЕ / ЧЛЕНСТВО (если есть, необязательно)
B20: Страхование профессиональной ответственности — в год, ₽ | C20: 10000
B21: Итого страхование в месяц (расчёт) | C21: =C20/12 -> 833.33333
B22: ИТОГО НАКЛАДНЫХ РАСХОДОВ В МЕСЯЦ | C22: =C10+C14+C18+C21 -> 16833.333
B24: 📊 5. РАСЧЁТ % НАКЛАДНЫХ ДЛЯ КАЛЬКУЛЯТОРА
B25: Плановая выручка от услуг в месяц, ₽ | C25: 300000 | D25: Введите ожидаемый месячный оборот. Чем он выше, тем ниже % накладных на 1 заказ.
B26: Расчётный % накладных (на себестоимость заказа) | C26: =IF(C25/(1+Настройки!C9)-C22>0,C22/(C25/(1+Настройки!C9)-C22),0) -> 0.078684006 | D26: Процент считается от прямых затрат: при выручке из C25 и наценке из «Настроек» накладные покрываются полностью.
B27: Часов работы в месяц для плановой выручки (≈) | C27: =C25/(Настройки!C5*(1+C26)*(1+Настройки!C9)) -> 213.9359 | D27: Норма рабочего времени ≈ 165 ч/мес. Если больше — план по выручке нереален при текущих ставках.

Sheet Рынок ЯО
B1: ЦЕНЫ КОНКУРЕНТОВ — ЯРОСЛАВЛЬ И ОБЛАСТЬ
B2: Открытые прайсы, поиск октябрь 2026. Цены «от» — нижняя граница; верхняя — оценка. Правьте под свои наблюдения.
B3: Услуга | C3: От, ₽ | D3: До, ₽ | E3: Откуда цифры | F3: Источник
B4: Обследование дома/здания, тех. заключение | C4: 30000 | D4: 80000 | E4: Общий осмотр 15–30 тыс.; с приборами и проверкой конструкций 30–80 тыс.; ФНЭ — от 20 тыс. | F4: yaroslavl.fesud.ru/obsledovanie-i-ekspertiza-doma
B5: Экспертиза залива (акт, причина, смета) | C5: 8000 | D5: 30000 | E5: Оценщики: ущерб от 6–8 тыс. (без причины); экспертные компании — от 20 тыс. | F5: expert-yaroslavl.ru/ekspertiza-zaliv
B6: Осмотр — Квартира (новостройка) | C6: 5000 | D6: 10000 | E6: Приёмка: 5 000 ₽ за 1-к + 1 000 ₽ за комнату, тепловизор в сезон | F6: uslugi.yandex.ru; profocenchik.ru/yaroslavl
B7: Осмотр — Квартира (вторичка) | C7: 7000 | D7: 15000 | E7: Мало данных — оценка между приёмкой и осмотром дома | F7: —
B8: Осмотр — Частный дом | C8: 15000 | D8: 30000 | E8: ФНЭ — от 20 тыс.; общий осмотр 15–30 тыс. | F8: yaroslavl.fesud.ru
B9: Осмотр — Нежилое помещение | C9: 15000 | D9: 30000 | E9: По аналогии с домом | F9: —

Sheet Расстояния ЯО
B1: РАССТОЯНИЯ ОТ ЯРОСЛАВЛЯ (в одну сторону, по дороге)
B2: ≈ ориентир. Уточните маршрут в Яндекс.Картах и поправьте цифру. Вписывайте км на листе расчёта.
B3: Населённый пункт | C3: км | D3: Время в пути туда-обратно
B4: Ярославль (в черте города) | C4: 15 | D4: =C4*2/Настройки!$C$25 -> 0.6
B5: Ярославский р-н (пригород) | C5: 25 | D5: =C5*2/Настройки!$C$25 -> 1
B6: Тутаев | C6: 35 | D6: =C6*2/Настройки!$C$25 -> 1.4
B7: Гаврилов-Ям | C7: 40 | D7: =C7*2/Настройки!$C$25 -> 1.6
B8: Некрасовское | C8: 40 | D8: =C8*2/Настройки!$C$25 -> 1.6
B9: Большое Село | C9: 55 | D9: =C9*2/Настройки!$C$25 -> 2.2
B10: Ростов | C10: 57 | D10: =C10*2/Настройки!$C$25 -> 2.28
B11: Данилов | C11: 70 | D11: =C11*2/Настройки!$C$25 -> 2.8
B12: Борисоглебский | C12: 75 | D12: =C12*2/Настройки!$C$25 -> 3
B13: Рыбинск | C13: 85 | D13: =C13*2/Настройки!$C$25 -> 3.4
B14: Любим | C14: 100 | D14: =C14*2/Настройки!$C$25 -> 4
B15: Пречистое | C15: 105 | D15: =C15*2/Настройки!$C$25 -> 4.2
... B21: Брейтово | C21: 180 | D21: =C21*2/Настройки!$C$25 -> 7.2

Sheet Обследование зданий
B1: ОБСЛЕДОВАНИЕ ЗДАНИЙ И СООРУЖЕНИЙ — РАСЧЁТ СТОИМОСТИ
B2: Техническое состояние конструкций, дефекты, акт/техническое заключение • ставки — с листа «Настройки»
B3: Параметр | C3: Значение / Выбор | D3: Часов / ед. | E3: Стоимость, ₽ | F3: Пояснение
B4: 🏢 1. ПАРАМЕТРЫ ОБЪЕКТА
B5: Тип объекта | C5: Частный дом
B6: Площадь объекта, м² | C6: 100
B7: Этаж / этажность | C7: 2 | F7: Для домов — этажность, для квартир — этаж расположения (справочно)
B8: ⏱ 2. ТРУДОЗАТРАТЫ
B9: Выезд и визуальный осмотр, часов | D9: 3 | E9: =D9*Настройки!$C$5 -> 3000
B10: Норма доп. часов на каждые 50 м² сверх 50 м² | D10: 1.5
B11: Доп. часы по площади (расчёт) | D11: =ROUNDUP(MAX(C6-50,0)/50,0)*D10 -> 1.5 | E11: =D11*Настройки!$C$5 -> 1500
B12: Инструментальные замеры (трещины, отклонения, влажность), часов | D12: 2 | E12: =D12*Настройки!$C$5 -> 2000
B13: Обработка данных и составление заключения, часов | D13: 30 | E13: =D13*Настройки!$C$5 -> 30000
B14: Итого часов и стоимость работ | D14: =D9+D11+D12+D13 -> 36.5 | E14: =SUM(E9:E13) -> 36500
B15: 🧰 3. ДОПОЛНИТЕЛЬНОЕ ОБОРУДОВАНИЕ
B16: Влагомер? | C16: ДА | E16: =IF(C16="ДА",Настройки!$C$14,0) -> 300
B17: Тепловизор? | C17: ДА | E17: =IF(C17="ДА",Настройки!$C$15,0) -> 800
B18: Лазерный дальномер? | C18: ДА | E18: =IF(C18="ДА",Настройки!$C$16,0) -> 150
B19: Эндоскоп (скрытые полости)? | C19: ДА | E19: =IF(C19="ДА",Настройки!$C$17,0) -> 500
B20: Итого дополнительное оборудование | E20: =SUM(E16:E19) -> 1750
B21: 🚗 ВЫЕЗД И ТРАНСПОРТ
B22: Расстояние до объекта, км (в одну сторону) | C22: 15 | F22: Ярославль ≈15 км, Рыбинск ≈85, Углич ≈120 — см. лист «Расстояния ЯО»
B23: Количество поездок (обычно 2 = туда-обратно) | C23: 2
B24: Транспорт + время в пути | E24: =C22*C23*Настройки!$C$6+C22*C23/Настройки!$C$25*Настройки!$C$5*Настройки!$C$26 -> 960
B25: 🖨 ОФОРМЛЕНИЕ ЗАКЛЮЧЕНИЯ
B26: Количество экземпляров | C26: =Настройки!$C$20 -> 2
B27: Стоимость печати/брошюровки | E27: =C26*Настройки!$C$19 -> 400
B28: Срочность (осмотр/акт в течение суток)? | C28: НЕТ
B29: 💰 6. ИТОГО — СВОДНЫЙ РАСЧЁТ
B30: Стоимость работ (п.2) | E30: =E14 -> 36500
B31: Дополнительное оборудование (п.3) | E31: =E20 -> 1750
B32: Транспорт (п.4) | E32: =E24 -> 960
B33: Печать / оформление (п.5) | E33: =E27 -> 400
B34: Себестоимость (прямые затраты) | E34: =SUM(E30:E33) -> 39610
B35: Накладные расходы (% из «Настройки») | E35: =E34*Настройки!$C$8 -> 3116.6735
B36: Итого затраты | E36: =E34+E35 -> 42726.673
B37: Наценка / плановая прибыль (% из «Настройки») | E37: =E36*Настройки!$C$9 -> 12818.002
B38: Цена без учёта срочности | E38: =E36+E37 -> 55544.675
B39: Надбавка за срочность (если включена) | E39: =IF(C28="ДА",E38*Настройки!$C$10,0) -> 0
B40: ИТОГОВАЯ ЦЕНА КЛИЕНТУ | E40: =ROUNDUP((E38+E39)/Настройки!$C$27,0)*Настройки!$C$27 -> 56000
...

Sheet Экспертиза залива
B1: ЭКСПЕРТИЗА ПОСЛЕ ЗАЛИВА — РАСЧЁТ СТОИМОСТИ
B2: Фиксация повреждений, причина залива, акт • опционально — смета стоимости ремонта • ставки — с листа «Настройки»
B3: Параметр | C3: Значение / Выбор | D3: Часов / ед. | E3: Стоимость, ₽ | F3: Пояснение
B4: 🏢 1. ПАРАМЕТРЫ ЗАЛИВА
B5: Тип объекта | C5: Частный дом
B6: Количество повреждённых помещений (комнат) | C6: 2
B7: Общая площадь повреждений, м² | C7: 25
B8: ⏱ 2. ТРУДОЗАТРАТЫ НА ОСМОТР И АКТ
B9: Выезд и общий осмотр, часов (базовые) | D9: 2 | E9: =D9*Настройки!$C$5 -> 2000
B10: Норма часов осмотра на 1 повреждённое помещение | D10: 1
B11: Часы на осмотр помещений (расчёт) | D11: =C6*D10 -> 2 | E11: =D11*Настройки!$C$5 -> 2000
B12: Фотофиксация и замеры , часов | D12: 1.5 | E12: =D12*Настройки!$C$5 -> 1500
B13: Составление акта осмотра / заключения, часов | D13: 8 | E13: =D13*Настройки!$C$5 -> 8000 | F13: Было 20 ч. При 20 ч цена втрое выше рынка Ярославля (8–30 тыс.).
B14: Итого часов и стоимость осмотра/акта | D14: =D9+D11+D12+D13 -> 13.5 | E14: =SUM(E9:E13) -> 13500
B15: 🧰 3. ДОПОЛНИТЕЛЬНОЕ ОБОРУДОВАНИЕ
B16: Влагомер? | C16: НЕТ | E16: =IF(C16="ДА",Настройки!$C$14,0) -> 0
B17: Тепловизор? | C17: НЕТ | E17: =IF(C17="ДА",Настройки!$C$15,0) -> 0
B18: Лазерный дальномер? | C18: НЕТ | E18: =IF(C18="ДА",Настройки!$C$16,0) -> 0
B19: Эндоскоп (скрытые полости)? | C19: НЕТ | E19: =IF(C19="ДА",Настройки!$C$17,0) -> 0
B20: Итого дополнительное оборудование | E20: =SUM(E16:E19) -> 0
B21: 🔁 4. ПОВТОРНЫЙ ВЫЕЗД (после высыхания — скрытые повреждения)
B22: Нужен повторный выезд? | C22: НЕТ
B23: Часы на повторный выезд и доп. осмотр | D23: 2 | E23: =IF(C22="ДА",D23*Настройки!$C$5,0) -> 0
B24: 🚗 ВЫЕЗД И ТРАНСПОРТ
B25: Расстояние до объекта, км (в одну сторону) | C25: 15 | F25: Ярославль ≈15 км, Рыбинск ≈85, Углич ≈120 — см. лист «Расстояния ЯО»
B26: Количество поездок (обычно 2 = туда-обратно) | C26: 2
B27: Транспорт + время в пути | E27: =C25*C26*(1+(C22="ДА"))*Настройки!$C$6+C25*C26*(1+(C22="ДА"))/Настройки!$C$25*Настройки!$C$5*Настройки!$C$26 -> 960 | F27: Повторный выезд (п.4 = ДА) удваивает поездки автоматически.
B28: 📐 6. СМЕТА УЩЕРБА (СТОИМОСТЬ РЕМОНТА) — ОПЦИОНАЛЬНО
B29: Составлять смету ущерба (стоимости ремонта)? | C29: ДА
B30: Норма часов на смету по 1 повреждённому помещению | D30: 2
B31: Часы на смету (расчёт) | D31: =IF(C29="ДА",C6*D30,0) -> 4 | E31: =D31*Настройки!$C$5 -> 4000
F32: Смета оценивает стоимость ремонта по укрупнённым расценкам — отдельная работа сверх акта осмотра.
B33: 🖨 ОФОРМЛЕНИЕ ЗАКЛЮЧЕНИЯ
B34: Количество экземпляров | C34: =Настройки!$C$20 -> 2
B35: Стоимость печати/брошюровки | E35: =C34*Настройки!$C$19 -> 400
B36: Срочность (осмотр/акт в течение суток)? | C36: НЕТ
B37: 💰 8. ИТОГО — СВОДНЫЙ РАСЧЁТ
B38: Стоимость работ — осмотр и акт (п.2) | E38: =E14 -> 13500
B39: Повторный выезд (п.4) | E39: =E23 -> 0
B40: Дополнительное оборудование (п.3) | E40: =E20 -> 0
...

Sheet Осмотр перед покупкой
B1: ОСМОТР ОБЪЕКТА ПЕРЕД ПОКУПКОЙ — РАСЧЁТ СТОИМОСТИ
B2: Визуальный осмотр, выявление дефектов, акт с перечнем замечаний • ставки — с листа «Настройки»
B3: Параметр | C3: Значение / Выбор | D3: Часов / ед. | E3: Стоимость, ₽ | F3: Пояснение
B4: 🏠 1. ПАРАМЕТРЫ ОБЪЕКТА
B5: Тип объекта | C5: Частный дом
B6: Площадь объекта, м² | C6: 120
B7: Количество комнат / помещений для осмотра | C7: 6
B8: ⏱ 2. ТРУДОЗАТРАТЫ
B9: Выезд и визуальный осмотр, часов (базовые) | D9: 2 | E9: =D9*Настройки!$C$5 -> 2000
B10: Норма доп. часов на 1 комнату сверх 3-х | D10: 0.5
B11: Доп. часы по количеству комнат (расчёт) | D11: =MAX(C7-3,0)*D10 -> 1.5 | E11: =D11*Настройки!$C$5 -> 1500
B12: Инструментальная проверка (влажность, окна, коммуникации), часов | D12: 1.5 | E12: =D12*Настройки!$C$5 -> 1500
B13: Составление акта осмотра с перечнем дефектов, часов | D13: 8 | E13: =D13*Настройки!$C$5 -> 8000
B14: Итого часов и стоимость работ | D14: =D9+D11+D12+D13 -> 13 | E14: =SUM(E9:E13) -> 13000
B15: 🧰 3. ДОПОЛНИТЕЛЬНОЕ ОБОРУДОВАНИЕ
B16: Влагомер? | C16: НЕТ | E16: =IF(C16="ДА",Настройки!$C$14,0) -> 0
B17: Тепловизор? | C17: НЕТ | E17: =IF(C17="ДА",Настройки!$C$15,0) -> 0
B18: Лазерный дальномер? | C18: НЕТ | E18: =IF(C18="ДА",Настройки!$C$16,0) -> 0
B19: Эндоскоп (скрытые полости)? | C19: НЕТ | E19: =IF(C19="ДА",Настройки!$C$17,0) -> 0
B20: Итого дополнительное оборудование | E20: =SUM(E16:E19) -> 0
B21: 🚗 ВЫЕЗД И ТРАНСПОРТ
B22: Расстояние до объекта, км (в одну сторону) | C22: 15 | F22: Ярославль ≈15 км, Рыбинск ≈85, Углич ≈120 — см. лист «Расстояния ЯО»
B23: Количество поездок (обычно 2 = туда-обратно) | C23: 2
B24: Транспорт + время в пути | E24: =C22*C23*Настройки!$C$6+C22*C23/Настройки!$C$25*Настройки!$C$5*Настройки!$C$26 -> 960
B25: 🖨 ОФОРМЛЕНИЕ АКТА
B26: Количество экземпляров | C26: =Настройки!$C$20 -> 2
B27: Стоимость печати/брошюровки | E27: =C26*Настройки!$C$19 -> 400
B28: Срочность (осмотр/акт в течение суток)? | C28: НЕТ
B29: 💰 6. ИТОГО — СВОДНЫЙ РАСЧЁТ
B30: Стоимость работ (п.2) | E30: =E14 -> 13000
B31: Дополнительное оборудование (п.3) | E31: =E20 -> 0
B32: Транспорт (п.4) | E32: =E24 -> 960
B33: Печать / оформление акта (п.5) | E33: =E27 -> 400
B34: Себестоимость (прямые затраты) | E34: =SUM(E30:E33) -> 14360
B35: Накладные расходы (% из «Настройки») | E35: =E34*Настройки!$C$8 -> 1129.9023
B36: Итого затраты | E36: =E34+E35 -> 15489.902
B37: Наценка / плановая прибыль (% из «Настройки») | E37: =E36*Настройки!$C$9 -> 4646.9707
B38: Цена без учёта срочности | E38: =E36+E37 -> 20136.873
B39: Надбавка за срочность (если включена) | E39: =IF(C28="ДА",E38*Настройки!$C$10,0) -> 0
B40: ИТОГОВАЯ ЦЕНА КЛИЕНТУ | E40: =ROUNDUP((E38+E39)/Настройки!$C$27,0)*Настройки!$C$27 -> 20500
...
